Workbook
Name \G: #REF!
Name \P: #REF!
Name \Q: #REF!
Name \S: #REF!
Name ___CAR3: #REF!
Name ___CLS10: #REF!
Name ___CLS7: #REF!
Name ___CLS8: #REF!
Name ___CLS9: #REF!
Name ___NCL3: #REF!
Name ___PA7: #REF!
Name ___PA8: #REF!
Name ___PAL1: #REF!
Name ___PAL2: #REF!
Name ___PAL3: #REF!
Name ___PAL4: #REF!
Name ___PAL5: #REF!
Name ___PAL6: #REF!
Name ___PAL7: #REF!
Name ___PAL8: #REF!
Name ___PAL9: #REF!
Name ___PD1: #REF!
Name ___PE12: #REF!
Name ___PE13: #REF!
Name ___PE6: #REF!
Name ___PE7: #REF!
Name ___PE8: #REF!
Name ___PE9: #REF!
Name ___PH1: #REF!
Name ___PI1: #REF!
Name ___PK1: #REF!
Name ___PK3: #REF!
Name __bookmark_3: #REF!
Name __bookmark_4: #REF!
Name __bookmark_5: #REF!
Name __bookmark_6: #REF!
Name __bookmark_7: #REF!
Name __CAR3: #REF!
Name __CLS10: #REF!
Name __CLS7: #REF!
Name __CLS8: #REF!
Name __CLS9: #REF!
Name __NCL3: #REF!
Name __PA7: #REF!
Name __PA8: #REF!
Name __PAL1: #REF!
Name __PAL2: #REF!
Name __PAL3: #REF!
Name __PAL4: #REF!
Name __PAL5: #REF!
Name __PAL6: #REF!
Name __PAL7: #REF!
Name __PAL8: #REF!
Name __PAL9: #REF!
Name __PD1: #REF!
Name __PE12: #REF!
Name __PE13: #REF!
Name __PE6: #REF!
Name __PE7: #REF!
Name __PE8: #REF!

Sheet Portfolio Listing
B2: PORTFOLIO Listing
B3: 45657
I4: =#REF! -> #REF!
B5: Kingsway Investment Ltd | D5: Nature | I5: Invested Capital | M5: Realized Value | P5: Unrealized Value | R5: Fund Performance | W5: Expected Return | AB5: Fund Term
B6: No. | C6: Project | D6: Geography | E6: Sector | F6: Asset | G6: Nature | H6: Investment Date | I6: Committed | J6: Funded | K6: Unfunded (O/S) | M6: Distribution | N6: Syndication | P6: MTM Fair Value | R6: DPI (x) | S6: RVPI (x) | T6: TVPI/MOIC (x) | U6: IRR | W6: Upside | X6: Total | Y6: MoIC | Z6: IRR | AB6: Inception | AC6: Expiry | AD6: Entity | AE6: Fee % | AF6: Carry % | AG6: Q3 CAS | AH6: Q3 Investment Report | AI6: Q3 Financial Statements | AJ6: Contributed | AK6: Distributed/ Realised | AL6: Deal expense | AM6: MTM/Unrealised
B7: =ROW()-6 -> 1 | C7: BOYU Capital Fund I | D7: China | E7: Diversified | F7: PE - VC / Growth | G7: Private | H7: 40695 | I7: ='BOYU Capital Fund I'!E10*10^6 -> 30000000 | J7: =-'BOYU Capital Fund I CF'!M2 -> 29454452 | K7: =IF(J7-I7>0,"0",J7-I7) -> -545547.98 | L7: =-K7/I7 -> 0.018184933 | M7: ='BOYU Capital Fund I CF'!M3 -> 92038826 | N7: 0 | P7: ='BOYU Capital Fund I CF'!M4 -> 51248 | R7: =M7/J7 -> 3.1247849 | S7: =P7/J7 -> 0.0017399068 | T7: ='BOYU Capital Fund I'!E18 -> 3.1265248 | U7: ='BOYU Capital Fund I'!E19 -> 0.3363551 | W7: {=SUM(VLOOKUP($C7,'Portfolio Summary'!$C$6:$AO$28,{28,29,30,31,32,33,34},FALSE))} -> 16900319 | X7: =VLOOKUP(C7,'Portfolio Summary'!$C$6:$T$27,14,0) -> 0 | Y7: =VLOOKUP(C7,'Portfolio Summary'!$C$6:$AN$26,3,0) -> 3.1042404 | Z7: =VLOOKUP(C7,'Portfolio Summary'!$C$6:$AN$26,2,0) -> 0.34753879 | AB7: ='BOYU Capital Fund I'!B3 -> 40705 | AC7: 44358 | AD7: CCGBVI | AE7: 2 | AF7: 20 | AG7: Y | AH7: Y | AI7: Y | AJ7: =-J7 -> -29454452 | AK7: =M7 -> 92038826 | AM7: =P7 -> 51248 | AO7: BOYU Capital Fund I, L.P.
B8: =B7+1 -> 2 | C8: Ascendent Fund | D8: China | E8: Diversified | F8: PE - Buyout | G8: Private | H8: 40878 | I8: ='Ascendent CP I'!E10*10^6 -> 10000000 | J8: =-'Ascendant CP I CF'!N2 -> 8570276.4 | K8: =IF(J8-I8>0,"0",J8-I8) -> -1429723.6 | L8: =-K8/I8 -> 0.14297236 | M8: ='Ascendant CP I CF'!N3 -> 20207464 | N8: 0 | P8: ='Ascendant CP I CF'!N4 -> 249627 | R8: =M8/J8 -> 2.3578545 | S8: =P8/J8 -> 0.029127065 | T8: ='Ascendent CP I'!E18 -> 2.3869815 | U8: ='Ascendent CP I'!E19 -> 0.22429716 | W8: {=SUM(VLOOKUP($C8,'Portfolio Summary'!$C$6:$AO$28,{28,29,30,31,32,33,34},FALSE))} -> 8917875.7 | X8: =VLOOKUP(C8,'Portfolio Summary'!$C$6:$T$27,14,0) -> 0 | Y8: =VLOOKUP(C8,'Portfolio Summary'!$C$6:$AN$26,3,0) -> 2.3365704 | Z8: =VLOOKUP(C8,'Portfolio Summary'!$C$6:$AN$26,2,0) -> 0.2338096 | AB8: ='Ascendent CP I'!B3 -> 40651 | AC8: =AB8+365*10 -> 44301 | AD8: CCGBVI | AE8: 2 | AF8: 20 | AG8: Y | AH8: Y | AI8: N | AO8: Ascendent Capital Partners I, L.P.
B9: =B8+1 -> 3 | C9: BOYU Capital Offshore Fund | D9: China | E9: Diversified | F9: HF | G9: PIPP | H9: 42614 | I9: 10000000 | J9: =-'BOYU Offshore CF'!D5 -> 10000000 | K9: =IF(J9-I9>0,"0",J9-I9) -> 0 | L9: =-K9/I9 -> 0 | M9: ='BOYU Offshore CF'!D65 -> 20196163 | N9: 0 | P9: ='BOYU Offshore CF'!D60 -> 793271.37 | R9: =M9/J9 -> 2.0196163 | S9: =P9/J9 -> 0.079327137 | T9: ='BOYU Offshore CF'!D67 -> 2.0989434 | U9: ='BOYU Offshore CF'!D68 -> 0.16955446 | W9: {=SUM(VLOOKUP($C9,'Portfolio Summary'!$C$6:$AO$28,{28,29,30,31,32,33,34},FALSE))} -> 20506163 | X9: =VLOOKUP(C9,'Portfolio Summary'!$C$6:$T$27,14,0) -> 0 | Y9: =VLOOKUP(C9,'Portfolio Summary'!$C$6:$AN$26,3,0) -> 2.0506163 | Z9: =VLOOKUP(C9,'Portfolio Summary'!$C$6:$AN$26,2,0) -> 0.16178617 | AB9: 42618 | AC9: Nil | AD9: CCGBVI | AE9: 2 | AF9: 20 | AG9: N/A | AH9: N/A | AI9: N/A | AJ9: =-J9 -> -10000000 | AK9: =M9 -> 20196163 | AM9: =P9 -> 793271.37 | AO9: BOYU Capital Offshore Fund
B10: =B9+1 -> 4 | C10: E15 Fund I | D10: US | E10: Technology | F10: PE - VC / Growth | G10: VC | H10: 42894 | I10: ='E15 Fund I'!E10*10^6 -> 6000000 | J10: =-'E15 Fund I (CF) '!I2 -> 6000000 | K10: =IF(J10-I10>0,"0",J10-I10) -> 0 | L10: =-K10/I10 -> 0 | M10: ='E15 Fund I (CF) '!I3 -> 4158210.8 | N10: 0 | P10: ='E15 Fund I (CF) '!I4 -> 569305 | R10: =M10/J10 -> 0.69303513 | S10: =P10/J10 -> 0.094884167 | T10: ='E15 Fund I'!E18 -> 0.7879193 | U10: ='E15 Fund I'!E19 -> -0.084686515 | W10: {=SUM(VLOOKUP($C10,'Portfolio Summary'!$C$6:$AO$28,{28,29,30,31,32,33,34},FALSE))} -> 875897.13 | X10: =VLOOKUP(C10,'Portfolio Summary'!$C$6:$T$27,14,0) -> 0 | Y10: =VLOOKUP(C10,'Portfolio Summary'!$C$6:$AN$26,3,0) -> 0.8097018 | Z10: =VLOOKUP(C10,'Portfolio Summary'!$C$6:$AN$26,2,0) -> -0.066498433 | AB10: ='E15 Fund I'!B3 -> 42892 | AC10: 46874 | AD10: Fortune Wheel | AE10: 2 | AF10: 20 | AO10: E15 Fund I, LP
B11: =B10+1 -> 5 | C11: West Street Capital Partners VII | D11: Global | E11: Diversified | F11: PE - Buyout | G11: Private | H11: 43344 | I11: ='West Street VII'!E10*10^6 -> 25000000 | J11: =-'West Street VII (CF)'!N2 -> 20996048 | K11: =IF(J11-I11>0,"0",J11-I11) -> -4003952 | L11: =-K11/I11 -> 0.16015808 | M11: ='West Street VII (CF)'!N3 -> 14856555 | N11: 0 | P11: ='West Street VII (CF)'!N4 -> 14507335 | R11: =M11/J11 -> 0.70758816 | S11: =P11/J11 -> 0.69095551 | T11: ='West Street VII'!E18 -> 1.3985437 | U11: ='West Street VII'!E19 -> 0.14580788 | W11: {=SUM(VLOOKUP($C11,'Portfolio Summary'!$C$6:$AO$28,{28,29,30,31,32,33,34},FALSE))} -> 3037854.7 | X11: =VLOOKUP(C11,'Portfolio Summary'!$C$6:$T$27,14,0) -> 0 | Y11: =VLOOKUP(C11,'Portfolio Summary'!$C$6:$AN$26,3,0) -> 2 | Z11: =VLOOKUP(C11,'Portfolio Summary'!$C$6:$AN$26,2,0) -> 0.18804665 | AB11: ='West Street VII'!B4 -> 43313 | AC11: 46966 | AD11: VMG Ltd | AE11: 1 | AF11: 20 | AG11: Y | AH11: N | AI11: Y | AO11: West Street Capital Partners VII
B12: =B11+1 -> 6 | C12: C Ventures Fund II | D12: China | E12: Technology | F12: PE - VC / Growth | G12: Private | H12: 43373 | I12: ='C Ventures II'!E10*10^6 -> 20000000 | J12: =-'C Ventures II CF '!K2 -> 19929372 | K12: =IF(J12-I12>0,"0",J12-I12) -> -70627.64 | L12: =-K12/I12 -> 0.003531382 | M12: ='C Ventures II CF '!K3 -> 5324899 | N12: 0 | P12: ='C Ventures II CF '!K4 -> 16039005 | R12: =M12/J12 -> 0.26718849 | S12: =P12/J12 -> 0.80479226 | T12: ='C Ventures II'!E18 -> 1.0719808 | U12: ='C Ventures II'!E19 -> 0.017202333 | W12: {=SUM(VLOOKUP($C12,'Portfolio Summary'!$C$6:$AO$28,{28,29,30,31,32,33,34},FALSE))} -> 6046681.3 | X12: =VLOOKUP(C12,'Portfolio Summary'!$C$6:$T$27,14,0) -> 0 | Y12: =VLOOKUP(C12,'Portfolio Summary'!$C$6:$AN$26,3,0) -> 1.4331243 | Z12: =VLOOKUP(C12,'Portfolio Summary'!$C$6:$AN$26,2,0) -> 0.069602423 | AB12: ='C Ventures II'!B3 -> 43373 | AC12: =AB12+365*8 -> 46293 | AD12: CCGBVI | AE12: 2 | AF12: 20 | AG12: Y | AH12: N | AI12: Y | AO12: C Ventures Fund II, L.P.
B13: =B12+1 -> 7 | C13: DCP Capital Partners | D13: China | E13: Diversified | F13: PE - Buyout | G13: Private | H13: 43445 | I13: ='DCP I'!E10*10^6 -> 50000000 | J13: =-'DCP I (CF)'!M2 -> 59725670 | K13: =IF(J13-I13>0,"0",J13-I13) -> 0 | L13: =-K13/I13 -> 0 | M13: ='DCP I (CF)'!M3 -> 28599371 | N13: 0 | P13: ='DCP I (CF)'!M4 -> 41287985 | R13: =M13/J13 -> 0.47884554 | S13: =P13/J13 -> 0.69129379 | T13: ='DCP I'!E18 -> 1.1701393 | U13: ='DCP I'!E19 -> 0.061443415 | W13: {=SUM(VLOOKUP($C13,'Portfolio Summary'!$C$6:$AO$28,{28,29,30,31,32,33,34},FALSE))} -> -4903893.3 | X13: =VLOOKUP(C13,'Portfolio Summary'!$C$6:$T$27,14,0) -> 0 | Y13: =VLOOKUP(C13,'Portfolio Summary'!$C$6:$AN$26,3,0) -> 1.4123037 | Z13: =VLOOKUP(C13,'Portfolio Summary'!$C$6:$AN$26,2,0) -> 0.08650031 | AB13: ='DCP I'!B3 -> 43080 | AC13: =AB13+365*11 -> 47095 | AD13: CCGBVI | AE13: 2 | AF13: 20 | AG13: Y | AH13: Y | AI13: N | AO13: DCP Capital Partners, L.P.
B14: =B13+1 -> 8 | C14: E15 Fund 1.5 | D14: US | E14: Technology | F14: PE - VC / Growth | G14: FinTech | H14: 43466 | I14: ='E15 Fund 1.5 (liquidating)'!E10*10^6 -> 6000000 | J14: =-'E15 Fund 1.5(CF) '!M2 -> 4500000 | K14: =IF(J14-I14>0,"0",J14-I14) -> -1500000 | L14: =-K14/I14 -> 0.25 | M14: ='E15 Fund 1.5(CF) '!M3 -> 3034269.1 | N14: 0 | P14: ='E15 Fund 1.5(CF) '!M4 -> 42858 | R14: =M14/J14 -> 0.67428203 | S14: =P14/J14 -> 0.009524 | T14: ='E15 Fund 1.5 (liquidating)'!E18 -> 0.68380603 | U14: ='E15 Fund 1.5 (liquidating)'!E19 -> -0.38429492 | W14: {=SUM(VLOOKUP($C14,'Portfolio Summary'!$C$6:$AO$28,{28,29,30,31,32,33,34},FALSE))} -> 121480.17 | X14: =VLOOKUP(C14,'Portfolio Summary'!$C$6:$T$27,14,0) -> 0 | Y14: =VLOOKUP(C14,'Portfolio Summary'!$C$6:$AN$26,3,0) -> 0.65096887 | Z14: =VLOOKUP(C14,'Portfolio Summary'!$C$6:$AN$26,2,0) -> -0.92820831 | AB14: 43466 | AC14: 47484 | AD14: Fortune Wheel | AE14: 2 | AF14: 10 | AO14: E15 Fund 1.5, LP
B15: =B14+1 -> 9 | C15: Skycus China Fund | D15: China | E15: Diversified | F15: PE - VC / Growth | G15: Private | H15: 43632 | I15: ='Skycus China Fund'!E10*10^6 -> 30000000 | J15: =-'Skycus China CF'!M2 -> 30000000 | K15: =IF(J15-I15>0,"0",J15-I15) -> 0 | L15: =-K15/I15 -> 0 | M15: ='Skycus China CF'!M3 -> 5327911.5 | N15: 0 | P15: ='Skycus China CF'!M4 -> 39396376 | R15: =M15/J15 -> 0.17759705 | S15: =P15/J15 -> 1.3132125 | T15: ='Skycus China Fund'!E18 -> 1.4908096 | U15: ='Skycus China Fund'!E19 -> 0.072061196 | W15: {=SUM(VLOOKUP($C15,'Portfolio Summary'!$C$6:$AO$28,{28,29,30,31,32,33,34},FALSE))} -> 19951941 | X15: =VLOOKUP(C15,'Portfolio Summary'!$C$6:$T$27,14,0) -> 0 | Y15: =VLOOKUP(C15,'Portfolio Summary'!$C$6:$AN$26,3,0) -> 1.8 | Z15: =VLOOKUP(C15,'Portfolio Summary'!$C$6:$AN$26,2,0) -> 0.08682356 | AB15: ='Skycus China Fund'!B3 -> 43024 | AC15: 46172 | AD15: CCGBVI | AE15: 2 | AF15: 20 | AG15: Y | AH15: Y | AI15: Y | AO15: Skycus China Fund, L.P.
B16: =B15+1 -> 10 | C16: Hongshan Capital Venture Partners Fund VIII (AKA "Sequoia Capital China Venture Partners VIII") | D16: China | E16: Diversified | F16: PE - VC / Growth | G16: Private | H16: 44075 | I16: ='HSG Growth VIII'!E10*10^6 -> 4500000 | J16: =-'HSG Growth VIII (CF)'!L2 -> 4500000 | K16: =IF(J16-I16>0,"0",J16-I16) -> 0 | L16: =-K16/I16 -> 0 | M16: ='HSG Growth VIII (CF)'!L3 -> 0 | N16: 0 | P16: ='HSG Growth VIII (CF)'!L4 -> 4623800 | R16: =M16/J16 -> 0 | S16: =P16/J16 -> 1.0275111 | T16: ='HSG Growth VIII'!E18 -> 1.0275111 | U16: ='HSG Growth VIII'!E19 -> 0.0080131024 | W16: {=SUM(VLOOKUP($C16,'Portfolio Summary'!$C$6:$AO$28,{27,28,29,30,31,32,33,34,35,36,37,38,39},FALSE))} -> 8100000 | X16: =VLOOKUP(C16,'Portfolio Summary'!$C$6:$T$27,14,0) -> 0 | Y16: =VLOOKUP(C16,'Portfolio Summary'!$C$6:$AN$26,3,0) -> 2.8 | Z16: =VLOOKUP(C16,'Portfolio Summary'!$C$6:$AN$26,2,0) -> 0.17868194 | AB16: 44075 | AC16: Nil | AD16: CCGBVI | AE16: Nil | AF16: 15 | AG16: Y | AH16: N | AI16: N | AJ16: =-J16 -> -4500000 | AK16: =M16 -> 0 | AM16: =P16 -> 4623800 | AO16: HongShan Capital Venture Partners Fund VIII, L.P.
B17: =B16+1 -> 11 | C17: HongShan Capital Growth Partners Fund VI (AKA "Sequoia Capital China Growth Partners VI") | D17: China | E17: Diversified | F17: PE - VC / Growth | G17: Private | H17: 44075 | I17: ='HSG Growth VI'!E10*10^6 -> 15750000 | J17: =-'HSG Growth VI (CF) '!L2 -> 15750000 | K17: =IF(J17-I17>0,"0",J17-I17) -> 0 | L17: =-K17/I17 -> 0 | M17: ='HSG Growth VI (CF) '!L3 -> 121791 | N17: 0 | P17: ='HSG Growth VI (CF) '!L4 -> 18019138 | R17: =M17/J17 -> 0.0077327619 | S17: =P17/J17 -> 1.1440723 | T17: ='HSG Growth VI'!E18 -> 1.151805 | U17: ='HSG Growth VI'!E19 -> 0.040418962 | W17: {=SUM(VLOOKUP($C17,'Portfolio Summary'!$C$6:$AO$28,{27,28,29,30,31,32,33,34,35,36,37,38,39},FALSE))} -> 15706709 | X17: =VLOOKUP(C17,'Portfolio Summary'!$C$6:$T$27,14,0) -> 0 | Y17: =VLOOKUP(C17,'Portfolio Summary'!$C$6:$AN$26,3,0) -> 1.9945178 | Z17: =VLOOKUP(C17,'Portfolio Summary'!$C$6:$AN$26,2,0) -> 0.11862699 | AB17: 44075 | AC17: Nil | AD17: CCGBVI | AE17: Nil | AF17: 15 | AG17: Y | AH17: N | AI17: N | AJ17: =-J17 -> -15750000 | AK17: =M17 -> 121791 | AM17: =P17 -> 18019138 | AO17: HongShan Capital Growth Partners Fund VI, L.P.
B18: =B17+1 -> 12 | C18: West Street Capital Partners VIII | D18: Global | E18: Diversified | F18: PE - Buyout | G18: Private | H18: 44136 | I18: ='West Street VIII'!E10*10^6 -> 50000000 | J18: =-'West Street VIII (CF)'!N2 -> 33100000 | K18: =IF(J18-I18>0,"0",J18-I18) -> -16900000 | L18: =-K18/I18 -> 0.338 | M18: ='West Street VIII (CF)'!N3 -> 650000 | N18: 0 | P18: ='West Street VIII (CF)'!N4 -> 38945352 | R18: =M18/J18 -> 0.019637462 | S18: =P18/J18 -> 1.1765967 | T18: ='West Street VIII'!E18 -> 1.1962342 | U18: ='West Street VIII'!E19 -> 0.085717693 | W18: {=SUM(VLOOKUP($C18,'Portfolio Summary'!$C$6:$AO$28,{27,28,29,30,31,32,33,34,35,36,37,38,39},FALSE))} -> 50000000 | X18: =VLOOKUP(C18,'Portfolio Summary'!$C$6:$T$27,14,0) -> 0 | Y18: =VLOOKUP(C18,'Portfolio Summary'!$C$6:$AN$26,3,0) -> 2 | Z18: =VLOOKUP(C18,'Portfolio Summary'!$C$6:$AN$26,2,0) -> 0.16302718 | AB18: ='West Street VIII'!B3 -> 44136 | AC18: ='West Street VIII'!B4 -> 44774 | AD18: VMG Ltd | AE18: 1.5 | AF18: 20 | AG18: Y | AH18: N | AI18: Y | AO18: West Street Capital Partners VIII
B19: =B18+1 -> 13 | C19: DCP Capital Partners II | D19: China | E19: Diversified | F19: PE - Buyout | G19: Private | H19: 44166 | I19: ='DCP II'!E10*10^6 -> 100000000 | J19: =-'DCP II (CF) '!M2 -> 37438527 | K19: =IF(J19-I19>0,"0",J19-I19) -> -62561473 | L19: =-K19/I19 -> 0.62561473 | M19: ='DCP II (CF) '!M3 -> 2676323.4 | N19: 0 | P19: ='DCP II (CF) '!M4 -> 25000583 | R19: =M19/J19 -> 0.07148581 | S19: =P19/J19 -> 0.66777688 | T19: ='DCP II'!E18 -> 0.73926269 | U19: ='DCP II'!E19 -> -0.18608239 | W19: {=SUM(VLOOKUP($C19,'Portfolio Summary'!$C$6:$AO$28,{27,28,29,30,31,32,33,34,35,36,37,38,39},FALSE))} -> 55024118 | X19: =VLOOKUP(C19,'Portfolio Summary'!$C$6:$T$27,14,0) -> 0 | Y19: =VLOOKUP(C19,'Portfolio Summary'!$C$6:$AN$26,3,0) -> 1.8 | Z19: =VLOOKUP(C19,'Portfolio Summary'!$C$6:$AN$26,2,0) -> 0.16096521 | AB19: ='DCP II'!B3 -> 44478 | AC19: 48122 | AD19: CCGBVI | AE19: 2 | AF19: 20 | AG19: Y | AH19: Y | AI19: N | AO19: DCP Capital Partners II, L.P.
B20: =B19+1 -> 14 | C20: Skycus USD Fund II (AKA “Lionet Fund LP”) | D20: China | E20: Diversified | F20: PE - VC / Growth | G20: Private | H20: 44166 | I20: ='Lionet Fund'!E10*10^6 -> 15000000 | J20: =-'Lionet Fund CF'!M2 -> 15728508 | K20: =IF(J20-I20>0,"0",J20-I20) -> 0 | L20: =-K20/I20 -> 0 | M20: ='Lionet Fund CF'!M3 -> 2197607.1 | N20: 0 | P20: ='Lionet Fund CF'!M4 -> 11059809 | R20: =M20/J20 -> 0.13972127 | S20: =P20/J20 -> 0.70316959 | T20: ='Lionet Fund'!E18 -> 0.84289086 | U20: ='Lionet Fund'!E19 -> -0.046108851 | W20: {=SUM(VLOOKUP($C20,'Portfolio Summary'!$C$6:$AO$28,{27,28,29,30,31,32,33,34,35,36,37,38,39},FALSE))} -> 6771491.7 | X20: =VLOOKUP(C20,'Portfolio Summary'!$C$6:$T$27,14,0) -> 0 | Y20: =VLOOKUP(C20,'Portfolio Summary'!$C$6:$AN$26,3,0) -> 1.4305235 | Z20: =VLOOKUP(C20,'Portfolio Summary'!$C$6:$AN$26,2,0) -> 0.060594109 | AB20: ='Lionet Fund'!B3 -> 44013 | AC20: =AB20+365*9 -> 47298 | AD20: CCGBVI | AE20: 2 | AF20: 20 | AG20: Y | AH20: N | AI20: N | AJ20: =-J20 -> -15728508 | AK20: =M20 -> 2197607.1 | AM20: =P20 -> 11059809 | AO20: Skycus USD Fund II ("Lionet Fund")
B21: =B20+1 -> 15 | C21: BOYU Real Estate Fund I | D21: China | E21: Logistic/ Data Center | F21: PE - Real Estate | G21: Property | H21: 44197 | I21: ='Boyu Real Estate'!E10*10^6 -> 30000000 | J21: =-'Boyu Real Estate CF'!M2 -> 19364197 | K21: =IF(J21-I21>0,"0",J21-I21) -> -10635803 | L21: =-K21/I21 -> 0.35452677 | M21: ='Boyu Real Estate CF'!M3 -> 995489.23 | N21: 0 | P21: ='Boyu Real Estate CF'!M4 -> 15342150 | R21: =M21/J21 -> 0.051408754 | S21: =P21/J21 -> 0.79229468 | T21: ='Boyu Real Estate'!E18 -> 0.84370343 | U21: ='Boyu Real Estate'!E19 -> -0.095536217 | W21: {=SUM(VLOOKUP($C21,'Portfolio Summary'!$C$6:$AO$28,{27,28,29,30,31,32,33,34,35,36,37,38,39},FALSE))} -> 39000000 | X21: =VLOOKUP(C21,'Portfolio Summary'!$C$6:$T$27,14,0) -> 0 | Y21: =VLOOKUP(C21,'Portfolio Summary'!$C$6:$AN$26,3,0) -> 2.3 | Z21: =VLOOKUP(C21,'Portfolio Summary'!$C$6:$AN$26,2,0) -> 0.22333994 | AB21: 44197 | AC21: =AB21+365*10 -> 47847 | AD21: CCGBVI | AE21: 1.75 | AF21: 20 | AG21: Y | AH21: Y | AI21: Y | AJ21: =-J21 -> -19364197 | AK21: =M21 -> 995489.23 | AM21: =P21 -> 15342150 | AO21: Boyu Real Estate Fund I, LP
B22: =B21+1 -> 16 | C22: E15 Fund II | D22: Global | E22: Technology | F22: PE - VC / Growth | G22: VC | H22: 44197 | I22: ='E15 Fund II'!E10*10^6 -> 10000000 | J22: =-'E15 Fund II CF'!L2 -> 6595876.3 | K22: =IF(J22-I22>0,"0",J22-I22) -> -3404123.7 | L22: =-K22/I22 -> 0.34041237 | M22: ='E15 Fund II CF'!L3 -> 24622248 | N22: 0 | P22: ='E15 Fund II CF'!L4 -> 2681000 | R22: =M22/J22 -> 3.732976 | S22: =P22/J22 -> 0.40646608 | T22: ='E15 Fund II'!E18 -> 4.1394421 | U22: ='E15 Fund II'!E19 -> 4.4740932 | W22: {=SUM(VLOOKUP($C22,'Portfolio Summary'!$C$6:$AO$28,{28,29,30,31,32,33,34},FALSE))} -> 17791489 | X22: =VLOOKUP(C22,'Portfolio Summary'!$C$6:$T$27,14,0) -> 0 | Y22: =VLOOKUP(C22,'Portfolio Summary'!$C$6:$AN$26,3,0) -> 3.9922991 | Z22: =VLOOKUP(C22,'Portfolio Summary'!$C$6:$AN$26,2,0) -> 3.7867348 | AB22: 44197 | AC22: 47849 | AD22: Fortune Wheel | AE22: 2 | AF22: 20 | AG22: N | AH22: Y | AI22: N | AJ22: =-J22 -> -6595876.3 | AK22: =M22 -> 24622248 | AM22: =P22 -> 2681000 | AO22: E15 Fund II, LP
B23: =B22+1 -> 17 | C23: Cottonwood | D23: US | E23: Real Estate | F23: PE - Special Situations | G23: Private | H23: 45393 | I23: =Cottonwood!E10*10^6 -> 12500000 | J23: =-'Cottonwood (CF)'!N2 -> 3150647.5 | K23: =IF(J23-I23>0,"0",J23-I23) -> -9349352.5 | L23: =-K23/I23 -> 0.7479482 | M23: ='Cottonwood (CF)'!N3 -> 0 | N23: 0 | P23: ='Cottonwood (CF)'!N4 -> 3779467 | R23: =M23/J23 -> 0 | S23: =P23/J23 -> 1.1995842 | T23: =Cottonwood!E18 -> 1.1995842 | U23: =Cottonwood!E19 -> 0.44407232 | W23: {=SUM(VLOOKUP($C23,'Portfolio Summary'!$C$6:$AO$28,{27,28,29,30,31,32,33,34,35,36,37,38,39},FALSE))} -> 18875000 | X23: =VLOOKUP(C23,'Portfolio Summary'!$C$6:$T$27,14,0) -> 0 | Y23: =VLOOKUP(C23,'Portfolio Summary'!$C$6:$AN$26,3,0) -> 2.51 | Z23: =VLOOKUP(C23,'Portfolio Summary'!$C$6:$AN$26,2,0) -> 0.28061346 | AB23: 45383 | AC23: 2030 | AD23: CCGBVI | AE23: 1.5 | AF23: 20 | AO23: Cottonwood-WTT Real Estate Special Situations Fund, LP
B24: =B23+1 -> 18 | C24: Genedant Ventures I | D24: Global | E24: Diversified | F24: PE - VC / Growth | G24: VC | H24: 45518 | I24: ='Genedant Ventures'!E10*10^6 -> 37600000 | J24: =-'Genedent Ventures (CF)'!M2 -> 2954733 | K24: =IF(J24-I24>0,"0",J24-I24) -> -34645267 | L24: =-K24/I24 -> 0.92141668 | M24: 0 | N24: 0 | P24: ='Genedent Ventures (CF)'!L14 -> 2186280 | R24: =M24/J24 -> 0 | S24: =P24/J24 -> 0.73992472 | T24: ='Genedant Ventures'!E18 -> 0.73992472 | U24: ='Genedant Ventures'!E19 -> -0.67657796 | W24: {=SUM(VLOOKUP($C24,'Portfolio Summary'!$C$6:$AO$28,{27,28,29,30,31,32,33,34,35,36,37,38,39},FALSE))} -> 2216049.8 | X24: =VLOOKUP(C24,'Portfolio Summary'!$C$6:$T$27,14,0) -> 0 | Y24: =VLOOKUP(C24,'Portfolio Summary'!$C$6:$AN$26,3,0) -> 3.5 | Z24: =VLOOKUP(C24,'Portfolio Summary'!$C$6:$AN$26,2,0) -> 0.18861382 | AB24: 45413 | AC24: 49065 | AD24: BII | AE24: 2 | AF24: 20 | AO24: Genedant Ventures I
B25: =B24+1 -> 19 | C25: GTCR XIV Access Offshore LP | D25: US | E25: Diversified | F25: PE - Buyout | G25: Buyout | H25: 45261 | I25: 16940000 | J25: =-'GTCR (CF)'!M2 -> 1756064.1 | K25: =J25-I25 -> -15183936 | L25: =-K25/I25 -> 0.89633624 | M25: 0 | N25: 0 | P25: ='GTCR (CF)'!L14 -> 2093389 | R25: =M25/J25 -> 0 | S25: =P25/J25 -> 1.1920915 | T25: =(P25+M25)/J25 -> 1.1920915 | U25: ='GTCR (CF)'!M5 -> 1.5680467 | W25: {=SUM(VLOOKUP($C25,'Portfolio Summary'!$C$6:$AO$28,{27,28,29,30,31,32,33,34,35,36,37,38,39},FALSE))} -> 8470000 | X25: =VLOOKUP(C25,'Portfolio Summary'!$C$6:$T$27,14,0) -> 0 | Y25: =VLOOKUP(C25,'Portfolio Summary'!$C$6:$AN$26,3,0) -> 2.5 | Z25: =VLOOKUP(C25,'Portfolio Summary'!$C$6:$AN$26,2,0) -> 0.22347825 | AB25: 45292 | AC25: 48945 | AD25: VMG Ltd | AE25: 2 | AF25: 20 | AO25: GTCR XIV Access Offshore LP
C27: Total_PE Fund | I27: =SUM(I7:I26) -> 479290000 | J27: =SUM(J7:J26) -> 3.2951437e+08 | K27: =SUM(K7:K26) -> -1.6022981e+08 | M27: =SUM(M7:M26) -> 2.2500713e+08 | N27: =SUM(N7:N26) -> 0 | P27: =SUM(P7:P26) -> 2.3666798e+08 | Q27: d | R27: =M27/J27 -> 0.68284465 | T27: =(P27+M27)/J27 -> 1.4010773 | W27: =SUM(W7:W26) -> 2.9340918e+08 | X27: =SUM(X7:X26) -> 0 | Y27: ='Portfolio Summary'!E26 -> 1.4469843 | Z27: ='Portfolio Summary'!D26 -> 0.19990547
B35: 4 | C35: Ark Pacific Special Oppor Fund I | G35: Private | H35: 42887 | I35: 5000000 | J35: 3413271.4 | K35: -1586728.6 | M35: 3636000 | N35: 0 | P35: 488000 | R35: 1.0652537 | S35: 0.14297134 | T35: 1.208225 | U35: 0.037474552 | W35: #N/A | X35: #N/A | Y35: #N/A | Z35: #N/A | AB35: 42181 | AC35: 44738 | AD35: VPP | AE35: 2 | AF35: 15 | AG35: Y | AH35: Y | AI35: N

Sheet Portfolio Summary
B2: Kingsway Investment - PE Fund Investment Summary
D3: Forecast | F3: Up to date | H3: Nature | M3: Capital Investment | Q3: Realized Value | U3: 40908 | V3: =+EOMONTH(U3,12) -> 41274 | W3: =+EOMONTH(V3,12) -> 41639 | X3: =+EOMONTH(W3,12) -> 42004 | Y3: =+EOMONTH(X3,12) -> 42369 | Z3: =+EOMONTH(Y3,12) -> 42735 | AA3: =+EOMONTH(Z3,12) -> 43100 | AB3: =+EOMONTH(AA3,12) -> 43465 | AC3: =+EOMONTH(AB3,12) -> 43830 | ... AX3: =+EOMONTH(AW3,12) -> 51501
B4: No. | C4: PE Fund | D4: IRR | E4: MoIC | F4: IRR | G4: MoIC | H4: Geography | I4: Sector | J4: Asset | K4: Nature | L4: Investment Date | M4: Committed | N4: Funded | O4: O/S | Q4: Distribution | R4: Syndicated to Genedant | S4: MTM Value | T4: Total | U4: 0 | V4: =U4+1 -> 1 | W4: =V4+1 -> 2 | X4: =W4+1 -> 3 | Y4: =X4+1 -> 4 | Z4: =Y4+1 -> 5 | AA4: =Z4+1 -> 6 | AB4: =AA4+1 -> 7 | AC4: =AB4+1 -> 8 | ... AX4: =AW4+1 -> 29
B5: Net Cash Flow
B6: 1 | C6: BOYU Capital Fund I | D6: =IRR(U6:AX6) -> 0.34753879 | E6: =T65/-T41 -> 3.1042404 | F6: =+INDEX('Portfolio Listing'!$U$7:$U$28,MATCH(C6,'Portfolio Listing'!$C$7:$C$28,0)) -> 0.3363551 | G6: ='Portfolio Listing'!T7 -> 3.1265248 | H6: =VLOOKUP($C6,'Portfolio Listing'!$C$7:$AF$28,2,FALSE) -> China | I6: =VLOOKUP($C6,'Portfolio Listing'!$C$7:$AF$28,3,FALSE) -> Diversified | J6: =VLOOKUP($C6,'Portfolio Listing'!$C$7:$AF$28,4,FALSE) -> PE - VC / Growth | K6: Private | L6: ='Portfolio Listing'!H7 -> 40695 | M6: =VLOOKUP(C6,'Portfolio Listing'!$C$7:$AF$28,7,FALSE) -> 30000000 | N6: =VLOOKUP(C6,'Portfolio Listing'!$C$7:$AF$28,8,FALSE) -> 29454452 | O6: =IF(N6-M6>0,0,N6-M6) -> -545547.98 | Q6: =VLOOKUP(C6,'Portfolio Listing'!$C$7:$AF$28,11,FALSE) -> 92038826 | R6: =VLOOKUP(C6,'Portfolio Listing'!$C$7:$AF$28,12,FALSE) -> 0 | S6: =VLOOKUP(C6,'Portfolio Listing'!$C$7:$AF$28,14,FALSE) -> 51248 | T6: =SUM(U6:AX6) -> 62584374 | U6: =U41+U65 -> -2738663.8 | V6: =V41+V65 -> -12024167 | W6: =W41+W65 -> -892468.02 | X6: =X41+X65 -> -4209772.1 | Y6: =Y41+Y65 -> 15963275 | Z6: =Z41+Z65 -> 12562086 | AA6: =AA41+AA65 -> 22614615 | AB6: =AB41+AB65 -> 6209234.1 | ... AX6: =AX41+AX65 -> 0 | AZ6: =+INDEX('Portfolio Listing'!$AO$7:$AO$28,MATCH('Portfolio Summary'!$C6,'Portfolio Listing'!$C$7:$C$28,0)) -> BOYU Capital Fund I, L.P.
B7: =B6+1 -> 2 | C7: Ascendent Fund | D7: =IRR(U7:AX7) -> 0.2338096 | E7: =T66/-T42 -> 2.3365704 | F7: =+INDEX('Portfolio Listing'!$U$7:$U$28,MATCH(C7,'Portfolio Listing'!$C$7:$C$28,0)) -> 0.22429716 | G7: ='Portfolio Listing'!T8 -> 2.3869815 | H7: =VLOOKUP($C7,'Portfolio Listing'!$C$7:$AF$28,2,FALSE) -> China | I7: =VLOOKUP($C7,'Portfolio Listing'!$C$7:$AF$28,3,FALSE) -> Diversified | J7: =VLOOKUP($C7,'Portfolio Listing'!$C$7:$AF$28,4,FALSE) -> PE - Buyout | K7: Private | L7: ='Portfolio Listing'!H8 -> 40878 | M7: =VLOOKUP(C7,'Portfolio Listing'!$C$7:$AF$28,7,FALSE) -> 10000000 | N7: =VLOOKUP(C7,'Portfolio Listing'!$C$7:$AF$28,8,FALSE) -> 8570276.4 | O7: =IF(N7-M7>0,0,N7-M7) -> -1429723.6 | Q7: =VLOOKUP(C7,'Portfolio Listing'!$C$7:$AF$28,11,FALSE) -> 20207464 | R7: =VLOOKUP(C7,'Portfolio Listing'!$C$7:$AF$28,12,FALSE) -> 0 | S7: =VLOOKUP(C7,'Portfolio Listing'!$C$7:$AF$28,14,FALSE) -> 249627 | T7: =SUM(U7:AX7) -> 12237188 | U7: =U42+U66 -> 0 | V7: =V42+V66 -> -2337283.7 | W7: =W42+W66 -> -2121566.2 | X7: =X42+X66 -> -118164.22 | Y7: =Y42+Y66 -> -309527.97 | Z7: =Z42+Z66 -> 2864132.1 | AA7: =AA42+AA66 -> 3478488.3 | AB7: =AB42+AB66 -> 1917146.6 | ... AX7: =AX42+AX66 -> 0 | AZ7: =+INDEX('Portfolio Listing'!$AO$7:$AO$28,MATCH('Portfolio Summary'!$C7,'Portfolio Listing'!$C$7:$C$28,0)) -> Ascendent Capital Partners I, L.P.
B8: =B7+1 -> 3 | C8: BOYU Capital Offshore Fund | D8: =IRR(U8:AX8) -> 0.16178617 | E8: =T67/-T43 -> 2.0506163 | F8: =+INDEX('Portfolio Listing'!$U$7:$U$28,MATCH(C8,'Portfolio Listing'!$C$7:$C$28,0)) -> 0.16955446 | G8: ='Portfolio Listing'!T9 -> 2.0989434 | H8: =VLOOKUP($C8,'Portfolio Listing'!$C$7:$AF$28,2,FALSE) -> China | I8: =VLOOKUP($C8,'Portfolio Listing'!$C$7:$AF$28,3,FALSE) -> Diversified | J8: =VLOOKUP($C8,'Portfolio Listing'!$C$7:$AF$28,4,FALSE) -> HF | K8: PIPP | L8: ='Portfolio Listing'!H9 -> 42614 | M8: =VLOOKUP(C8,'Portfolio Listing'!$C$7:$AF$28,7,FALSE) -> 10000000 | N8: =VLOOKUP(C8,'Portfolio Listing'!$C$7:$AF$28,8,FALSE) -> 10000000 | O8: =IF(N8-M8>0,0,N8-M8) -> 0 | Q8: =VLOOKUP(C8,'Portfolio Listing'!$C$7:$AF$28,11,FALSE) -> 20196163 | R8: =VLOOKUP(C8,'Portfolio Listing'!$C$7:$AF$28,12,FALSE) -> 0 | S8: =VLOOKUP(C8,'Portfolio Listing'!$C$7:$AF$28,14,FALSE) -> 793271.37 | T8: =SUM(U8:AX8) -> 10506163 | U8: =U43+U67 -> 0 | V8: =V43+V67 -> 0 | W8: =W43+W67 -> 0 | X8: =X43+X67 -> 0 | Y8: =Y43+Y67 -> 0 | Z8: =Z43+Z67 -> -10000000 | AA8: =AA43+AA67 -> 0 | AB8: =AB43+AB67 -> 0 | ... AX8: =AX43+AX67 -> 0 | AZ8: =+INDEX('Portfolio Listing'!$AO$7:$AO$28,MATCH('Portfolio Summary'!$C8,'Portfolio Listing'!$C$7:$C$28,0)) -> BOYU Capital Offshore Fund
B9: =B8+1 -> 4 | C9: E15 Fund I | D9: =IRR(U9:AX9) -> -0.066498433 | E9: =T69/-T45 -> 0.8097018 | F9: =+INDEX('Portfolio Listing'!$U$7:$U$28,MATCH(C9,'Portfolio Listing'!$C$7:$C$28,0)) -> -0.084686515 | G9: ='Portfolio Listing'!T10 -> 0.7879193 | H9: =VLOOKUP($C9,'Portfolio Listing'!$C$7:$AF$28,2,FALSE) -> US | I9: =VLOOKUP($C9,'Portfolio Listing'!$C$7:$AF$28,3,FALSE) -> Technology | J9: =VLOOKUP($C9,'Portfolio Listing'!$C$7:$AF$28,4,FALSE) -> PE - VC / Growth | K9: VC | L9: ='Portfolio Listing'!H10 -> 42894 | M9: =VLOOKUP(C9,'Portfolio Listing'!$C$7:$AF$28,7,FALSE) -> 6000000 | N9: =VLOOKUP(C9,'Portfolio Listing'!$C$7:$AF$28,8,FALSE) -> 6000000 | O9: =IF(N9-M9>0,0,N9-M9) -> 0 | Q9: =VLOOKUP(C9,'Portfolio Listing'!$C$7:$AF$28,11,FALSE) -> 4158210.8 | R9: =VLOOKUP(C9,'Portfolio Listing'!$C$7:$AF$28,12,FALSE) -> 0 | S9: =VLOOKUP(C9,'Portfolio Listing'!$C$7:$AF$28,14,FALSE) -> 569305 | T9: =SUM(U9:AX9) -> -1141789.2 | U9: =U45+U69 -> 0 | V9: =V45+V69 -> 0 | W9: =W45+W69 -> 0 | X9: =X45+X69 -> 0 | Y9: =Y45+Y69 -> 0 | Z9: =Z45+Z69 -> 0 | AA9: =AA45+AA69 -> -6000000 | AB9: =AB45+AB69 -> 0 | ... AX9: =AX45+AX69 -> 0 | AZ9: =+INDEX('Portfolio Listing'!$AO$7:$AO$28,MATCH('Portfolio Summary'!$C9,'Portfolio Listing'!$C$7:$C$28,0)) -> E15 Fund I, LP
B10: =B9+1 -> 5 | C10: West Street Capital Partners VII | D10: =IRR(U10:AX10) -> 0.18804665 | E10: =T70/-T46 -> 2 | F10: =+INDEX('Portfolio Listing'!$U$7:$U$28,MATCH(C10,'Portfolio Listing'!$C$7:$C$28,0)) -> 0.14580788 | G10: ='Portfolio Listing'!T11 -> 1.3985437 | H10: =VLOOKUP($C10,'Portfolio Listing'!$C$7:$AF$28,2,FALSE) -> Global | I10: =VLOOKUP($C10,'Portfolio Listing'!$C$7:$AF$28,3,FALSE) -> Diversified | J10: =VLOOKUP($C10,'Portfolio Listing'!$C$7:$AF$28,4,FALSE) -> PE - Buyout | K10: Private | L10: ='Portfolio Listing'!H11 -> 43344 | M10: =VLOOKUP(C10,'Portfolio Listing'!$C$7:$AF$28,7,FALSE) -> 25000000 | N10: =VLOOKUP(C10,'Portfolio Listing'!$C$7:$AF$28,8,FALSE) -> 20996048 | O10: =IF(N10-M10>0,0,N10-M10) -> -4003952 | Q10: =VLOOKUP(C10,'Portfolio Listing'!$C$7:$AF$28,11,FALSE) -> 14856555 | R10: =VLOOKUP(C10,'Portfolio Listing'!$C$7:$AF$28,12,FALSE) -> 0 | S10: =VLOOKUP(C10,'Portfolio Listing'!$C$7:$AF$28,14,FALSE) -> 14507335 | T10: =SUM(U10:AX10) -> 25000000 | U10: =U46+U70 -> 0 | V10: =V46+V70 -> 0 | W10: =W46+W70 -> 0 | X10: =X46+X70 -> 0 | Y10: =Y46+Y70 -> 0 | Z10: =Z46+Z70 -> 0 | AA10: =AA46+AA70 -> 0 | AB10: =AB46+AB70 -> 0 | ... AX10: =AX46+AX70 -> 0 | AZ10: =+INDEX('Portfolio Listing'!$AO$7:$AO$28,MATCH('Portfolio Summary'!$C10,'Portfolio Listing'!$C$7:$C$28,0)) -> West Street Capital Partners VII
B11: =B10+1 -> 6 | C11: C Ventures Fund II | D11: =IRR(U11:AX11) -> 0.069602423 | E11: =T71/-T47 -> 1.4331243 | F11: =+INDEX('Portfolio Listing'!$U$7:$U$28,MATCH(C11,'Portfolio Listing'!$C$7:$C$28,0)) -> 0.017202333 | G11: ='Portfolio Listing'!T12 -> 1.0719808 | H11: =VLOOKUP($C11,'Portfolio Listing'!$C$7:$AF$28,2,FALSE) -> China | I11: =VLOOKUP($C11,'Portfolio Listing'!$C$7:$AF$28,3,FALSE) -> Technology | J11: =VLOOKUP($C11,'Portfolio Listing'!$C$7:$AF$28,4,FALSE) -> PE - VC / Growth | K11: Private | L11: ='Portfolio Listing'!H12 -> 43373 | M11: =VLOOKUP(C11,'Portfolio Listing'!$C$7:$AF$28,7,FALSE) -> 20000000 | N11: =VLOOKUP(C11,'Portfolio Listing'!$C$7:$AF$28,8,FALSE) -> 19929372 | O11: =IF(N11-M11>0,0,N11-M11) -> -70627.64 | Q11: =VLOOKUP(C11,'Portfolio Listing'!$C$7:$AF$28,11,FALSE) -> 5324899 | R11: =VLOOKUP(C11,'Portfolio Listing'!$C$7:$AF$28,12,FALSE) -> 0 | S11: =VLOOKUP(C11,'Portfolio Listing'!$C$7:$AF$28,14,FALSE) -> 16039005 | T11: =SUM(U11:AX11) -> 9066713.9 | U11: =U47+U71 -> 0 | V11: =V47+V71 -> 0 | W11: =W47+W71 -> 0 | X11: =X47+X71 -> 0 | Y11: =Y47+Y71 -> 0 | Z11: =Z47+Z71 -> 0 | AA11: =AA47+AA71 -> 0 | AB11: =AB47+AB71 -> -2000000 | ... AX11: =AX47+AX71 -> 0 | AZ11: =+INDEX('Portfolio Listing'!$AO$7:$AO$28,MATCH('Portfolio Summary'!$C11,'Portfolio Listing'!$C$7:$C$28,0)) -> C Ventures Fund II, L.P.
B12: =B11+1 -> 7 | C12: DCP Capital Partners | D12: =IRR(U12:AX12) -> 0.08650031 | E12: =T72/-T48 -> 1.4123037 | F12: =+INDEX('Portfolio Listing'!$U$7:$U$28,MATCH(C12,'Portfolio Listing'!$C$7:$C$28,0)) -> 0.061443415 | G12: ='Portfolio Listing'!T13 -> 1.1701393 | H12: =VLOOKUP($C12,'Portfolio Listing'!$C$7:$AF$28,2,FALSE) -> China | I12: =VLOOKUP($C12,'Portfolio Listing'!$C$7:$AF$28,3,FALSE) -> Diversified | J12: =VLOOKUP($C12,'Portfolio Listing'!$C$7:$AF$28,4,FALSE) -> PE - Buyout | K12: Private | L12: ='Portfolio Listing'!H13 -> 43445 | M12: =VLOOKUP(C12,'Portfolio Listing'!$C$7:$AF$28,7,FALSE) -> 50000000 | N12: =VLOOKUP(C12,'Portfolio Listing'!$C$7:$AF$28,8,FALSE) -> 59725670 | O12: =IF(N12-M12>0,0,N12-M12) -> 0 | Q12: =VLOOKUP(C12,'Portfolio Listing'!$C$7:$AF$28,11,FALSE) -> 28599371 | R12: =VLOOKUP(C12,'Portfolio Listing'!$C$7:$AF$28,12,FALSE) -> 0 | S12: =VLOOKUP(C12,'Portfolio Listing'!$C$7:$AF$28,14,FALSE) -> 41287985 | T12: =SUM(U12:AX12) -> 26274330 | U12: =U48+U72 -> 0 | V12: =V48+V72 -> 0 | W12: =W48+W72 -> 0 | X12: =X48+X72 -> 0 | Y12: =Y48+Y72 -> 0 | Z12: =Z48+Z72 -> 0 | AA12: =AA48+AA72 -> 0 | AB12: =AB48+AB72 -> 0 | ... AX12: =AX48+AX72 -> 0 | AZ12: =+INDEX('Portfolio Listing'!$AO$7:$AO$28,MATCH('Portfolio Summary'!$C12,'Portfolio Listing'!$C$7:$C$28,0)) -> DCP Capital Partners, L.P.
B13: =B12+1 -> 8 | C13: E15 Fund 1.5 | D13: =IRR(U13:AX13) -> -0.92820831 | E13: =T73/-T49 -> 0.65096887 | F13: =+INDEX('Portfolio Listing'!$U$7:$U$28,MATCH(C13,'Portfolio Listing'!$C$7:$C$28,0)) -> -0.38429492 | G13: ='Portfolio Listing'!T14 -> 0.68380603 | H13: =VLOOKUP($C13,'Portfolio Listing'!$C$7:$AF$28,2,FALSE) -> US | I13: =VLOOKUP($C13,'Portfolio Listing'!$C$7:$AF$28,3,FALSE) -> Technology | J13: =VLOOKUP($C13,'Portfolio Listing'!$C$7:$AF$28,4,FALSE) -> PE - VC / Growth | K13: FinTech | L13: ='Portfolio Listing'!H14 -> 43466 | M13: =VLOOKUP(C13,'Portfolio Listing'!$C$7:$AF$28,7,FALSE) -> 6000000 | N13: =VLOOKUP(C13,'Portfolio Listing'!$C$7:$AF$28,8,FALSE) -> 4500000 | O13: =IF(N13-M13>0,0,N13-M13) -> -1500000 | Q13: =VLOOKUP(C13,'Portfolio Listing'!$C$7:$AF$28,11,FALSE) -> 3034269.1 | R13: =VLOOKUP(C13,'Portfolio Listing'!$C$7:$AF$28,12,FALSE) -> 0 | S13: =VLOOKUP(C13,'Portfolio Listing'!$C$7:$AF$28,14,FALSE) -> 42858 | T13: =SUM(U13:AX13) -> -1570640.1 | U13: =U49+U73 -> 0 | V13: =V49+V73 -> 0 | W13: =W49+W73 -> 0 | X13: =X49+X73 -> 0 | Y13: =Y49+Y73 -> 0 | Z13: =Z49+Z73 -> 0 | AA13: =AA49+AA73 -> 0 | AB13: =AB49+AB73 -> 0 | ... AX13: =AX49+AX73 -> 0 | AZ13: =+INDEX('Portfolio Listing'!$AO$7:$AO$28,MATCH('Portfolio Summary'!$C13,'Portfolio Listing'!$C$7:$C$28,0)) -> E15 Fund 1.5, LP
B14: =B13+1 -> 9 | C14: Skycus China Fund | D14: =IRR(U14:AX14) -> 0.08682356 | E14: =T74/-T50 -> 1.8 | F14: =+INDEX('Portfolio Listing'!$U$7:$U$28,MATCH(C14,'Portfolio Listing'!$C$7:$C$28,0)) -> 0.072061196 | G14: ='Portfolio Listing'!T15 -> 1.4908096 | H14: =VLOOKUP($C14,'Portfolio Listing'!$C$7:$AF$28,2,FALSE) -> China | I14: =VLOOKUP($C14,'Portfolio Listing'!$C$7:$AF$28,3,FALSE) -> Diversified | J14: =VLOOKUP($C14,'Portfolio Listing'!$C$7:$AF$28,4,FALSE) -> PE - VC / Growth | K14: Private | L14: ='Portfolio Listing'!H15 -> 43632 | M14: =VLOOKUP(C14,'Portfolio Listing'!$C$7:$AF$28,7,FALSE) -> 30000000 | N14: =VLOOKUP(C14,'Portfolio Listing'!$C$7:$AF$28,8,FALSE) -> 30000000 | O14: =IF(N14-M14>0,0,N14-M14) -> 0 | Q14: =VLOOKUP(C14,'Portfolio Listing'!$C$7:$AF$28,11,FALSE) -> 5327911.5 | R14: =VLOOKUP(C14,'Portfolio Listing'!$C$7:$AF$28,12,FALSE) -> 0 | S14: =VLOOKUP(C14,'Portfolio Listing'!$C$7:$AF$28,14,FALSE) -> 39396376 | T14: =SUM(U14:AX14) -> 24000000 | U14: =U50+U74 -> 0 | V14: =V50+V74 -> 0 | W14: =W50+W74 -> 0 | X14: =X50+X74 -> 0 | Y14: =Y50+Y74 -> 0 | Z14: =Z50+Z74 -> 0 | AA14: =AA50+AA74 -> 0 | AB14: =AB50+AB74 -> -18000000 | ... AX14: =AX50+AX74 -> 0 | AZ14: =+INDEX('Portfolio Listing'!$AO$7:$AO$28,MATCH('Portfolio Summary'!$C14,'Portfolio Listing'!$C$7:$C$28,0)) -> Skycus China Fund, L.P.
B15: =B14+1 -> 10 | C15: Hongshan Capital Venture Partners Fund VIII (AKA "Sequoia Capital China Venture Partners VIII") | D15: =IRR(U15:AX15) -> 0.17868194 | E15: =T75/-T51 -> 2.8 | F15: =+INDEX('Portfolio Listing'!$U$7:$U$28,MATCH(C15,'Portfolio Listing'!$C$7:$C$28,0)) -> 0.0080131024 | G15: ='Portfolio Listing'!T16 -> 1.0275111 | H15: =VLOOKUP($C15,'Portfolio Listing'!$C$7:$AF$28,2,FALSE) -> China | I15: =VLOOKUP($C15,'Portfolio Listing'!$C$7:$AF$28,3,FALSE) -> Diversified | J15: =VLOOKUP($C15,'Portfolio Listing'!$C$7:$AF$28,4,FALSE) -> PE - VC / Growth | K15: Private | L15: ='Portfolio Listing'!H16 -> 44075 | M15: =VLOOKUP(C15,'Portfolio Listing'!$C$7:$AF$28,7,FALSE) -> 4500000 | N15: =VLOOKUP(C15,'Portfolio Listing'!$C$7:$AF$28,8,FALSE) -> 4500000 | O15: =IF(N15-M15>0,0,N15-M15) -> 0 | Q15: =VLOOKUP(C15,'Portfolio Listing'!$C$7:$AF$28,11,FALSE) -> 0 | R15: =VLOOKUP(C15,'Portfolio Listing'!$C$7:$AF$28,12,FALSE) -> 0 | S15: =VLOOKUP(C15,'Portfolio Listing'!$C$7:$AF$28,14,FALSE) -> 4623800 | T15: =SUM(U15:AX15) -> 8100000 | U15: =U51+U75 -> 0 | V15: =V51+V75 -> 0 | W15: =W51+W75 -> 0 | X15: =X51+X75 -> 0 | Y15: =Y51+Y75 -> 0 | Z15: =Z51+Z75 -> 0 | AA15: =AA51+AA75 -> 0 | AB15: =AB51+AB75 -> 0 | ... AX15: =AX51+AX75 -> 0 | AZ15: =+INDEX('Portfolio Listing'!$AO$7:$AO$28,MATCH('Portfolio Summary'!$C15,'Portfolio Listing'!$C$7:$C$28,0)) -> HongShan Capital Venture Partners Fund VIII, L.P.
B16: =B15+1 -> 11 | C16: HongShan Capital Growth Partners Fund VI (AKA "Sequoia Capital China Growth Partners VI") | D16: =IRR(U16:AX16) -> 0.11862699 | E16: =T76/-T52 -> 1.9945178 | F16: =+INDEX('Portfolio Listing'!$U$7:$U$28,MATCH(C16,'Portfolio Listing'!$C$7:$C$28,0)) -> 0.040418962 | G16: ='Portfolio Listing'!T17 -> 1.151805 | H16: =VLOOKUP($C16,'Portfolio Listing'!$C$7:$AF$28,2,FALSE) -> China | I16: =VLOOKUP($C16,'Portfolio Listing'!$C$7:$AF$28,3,FALSE) -> Diversified | J16: =VLOOKUP($C16,'Portfolio Listing'!$C$7:$AF$28,4,FALSE) -> PE - VC / Growth | K16: Private | L16: ='Portfolio Listing'!H17 -> 44075 | M16: =VLOOKUP(C16,'Portfolio Listing'!$C$7:$AF$28,7,FALSE) -> 15750000 | N16: =VLOOKUP(C16,'Portfolio Listing'!$C$7:$AF$28,8,FALSE) -> 15750000 | O16: =IF(N16-M16>0,0,N16-M16) -> 0 | Q16: =VLOOKUP(C16,'Portfolio Listing'!$C$7:$AF$28,11,FALSE) -> 121791 | R16: =VLOOKUP(C16,'Portfolio Listing'!$C$7:$AF$28,12,FALSE) -> 0 | S16: =VLOOKUP(C16,'Portfolio Listing'!$C$7:$AF$28,14,FALSE) -> 18019138 | T16: =SUM(U16:AX16) -> 15706709 | U16: =U52+U76 -> 0 | V16: =V52+V76 -> 0 | W16: =W52+W76 -> 0 | X16: =X52+X76 -> 0 | Y16: =Y52+Y76 -> 0 | Z16: =Z52+Z76 -> 0 | AA16: =AA52+AA76 -> 0 | AB16: =AB52+AB76 -> 0 | ... AX16: =AX52+AX76 -> 0 | AZ16: =+INDEX('Portfolio Listing'!$AO$7:$AO$28,MATCH('Portfolio Summary'!$C16,'Portfolio Listing'!$C$7:$C$28,0)) -> HongShan Capital Growth Partners Fund VI, L.P.
B17: =B16+1 -> 12 | C17: West Street Capital Partners VIII | D17: =IRR(U17:AX17) -> 0.16302718 | E17: =T77/-T53 -> 2 | F17: =+INDEX('Portfolio Listing'!$U$7:$U$28,MATCH(C17,'Portfolio Listing'!$C$7:$C$28,0)) -> 0.085717693 | G17: ='Portfolio Listing'!T18 -> 1.1962342 | H17: =VLOOKUP($C17,'Portfolio Listing'!$C$7:$AF$28,2,FALSE) -> Global | I17: =VLOOKUP($C17,'Portfolio Listing'!$C$7:$AF$28,3,FALSE) -> Diversified | J17: =VLOOKUP($C17,'Portfolio Listing'!$C$7:$AF$28,4,FALSE) -> PE - Buyout | K17: Private | L17: ='Portfolio Listing'!H18 -> 44136 | M17: =VLOOKUP(C17,'Portfolio Listing'!$C$7:$AF$28,7,FALSE) -> 50000000 | N17: =VLOOKUP(C17,'Portfolio Listing'!$C$7:$AF$28,8,FALSE) -> 33100000 | O17: =IF(N17-M17>0,0,N17-M17) -> -16900000 | Q17: =VLOOKUP(C17,'Portfolio Listing'!$C$7:$AF$28,11,FALSE) -> 650000 | R17: =VLOOKUP(C17,'Portfolio Listing'!$C$7:$AF$28,12,FALSE) -> 0 | S17: =VLOOKUP(C17,'Portfolio Listing'!$C$7:$AF$28,14,FALSE) -> 38945352 | T17: =SUM(U17:AX17) -> 50000000 | U17: =U53+U77 -> 0 | V17: =V53+V77 -> 0 | W17: =W53+W77 -> 0 | X17: =X53+X77 -> 0 | Y17: =Y53+Y77 -> 0 | Z17: =Z53+Z77 -> 0 | AA17: =AA53+AA77 -> 0 | AB17: =AB53+AB77 -> 0 | ... AX17: =AX53+AX77 -> 0 | AZ17: =+INDEX('Portfolio Listing'!$AO$7:$AO$28,MATCH('Portfolio Summary'!$C17,'Portfolio Listing'!$C$7:$C$28,0)) -> West Street Capital Partners VIII
B18: =B17+1 -> 13 | C18: DCP Capital Partners II | D18: =IRR(U18:AX18) -> 0.16096521 | E18: =T78/-T54 -> 1.8 | F18: =+INDEX('Portfolio Listing'!$U$7:$U$28,MATCH(C18,'Portfolio Listing'!$C$7:$C$28,0)) -> -0.18608239 | G18: ='Portfolio Listing'!T19 -> 0.73926269 | H18: =VLOOKUP($C18,'Portfolio Listing'!$C$7:$AF$28,2,FALSE) -> China | I18: =VLOOKUP($C18,'Portfolio Listing'!$C$7:$AF$28,3,FALSE) -> Diversified | J18: =VLOOKUP($C18,'Portfolio Listing'!$C$7:$AF$28,4,FALSE) -> PE - Buyout | K18: Private | L18: ='Portfolio Listing'!H19 -> 44166 | M18: =VLOOKUP(C18,'Portfolio Listing'!$C$7:$AF$28,7,FALSE) -> 100000000 | N18: =VLOOKUP(C18,'Portfolio Listing'!$C$7:$AF$28,8,FALSE) -> 37438527 | O18: =IF(N18-M18>0,0,N18-M18) -> -62561473 | Q18: =VLOOKUP(C18,'Portfolio Listing'!$C$7:$AF$28,11,FALSE) -> 2676323.4 | R18: =VLOOKUP(C18,'Portfolio Listing'!$C$7:$AF$28,12,FALSE) -> 0 | S18: =VLOOKUP(C18,'Portfolio Listing'!$C$7:$AF$28,14,FALSE) -> 25000583 | T18: =SUM(U18:AX18) -> 80000000 | U18: =U54+U78 -> 0 | V18: =V54+V78 -> 0 | W18: =W54+W78 -> 0 | X18: =X54+X78 -> 0 | Y18: =Y54+Y78 -> 0 | Z18: =Z54+Z78 -> 0 | AA18: =AA54+AA78 -> 0 | AB18: =AB54+AB78 -> 0 | ... AX18: =AX54+AX78 -> 0 | AZ18: =+INDEX('Portfolio Listing'!$AO$7:$AO$28,MATCH('Portfolio Summary'!$C18,'Portfolio Listing'!$C$7:$C$28,0)) -> DCP Capital Partners II, L.P.
B19: =B18+1 -> 14 | C19: Skycus USD Fund II (AKA “Lionet Fund LP”) | D19: =IRR(U19:AX19) -> 0.060594109 | E19: =T79/-T55 -> 1.4305235 | F19: =+INDEX('Portfolio Listing'!$U$7:$U$28,MATCH(C19,'Portfolio Listing'!$C$7:$C$28,0)) -> -0.046108851 | G19: ='Portfolio Listing'!T20 -> 0.84289086 | H19: =VLOOKUP($C19,'Portfolio Listing'!$C$7:$AF$28,2,FALSE) -> China | I19: =VLOOKUP($C19,'Portfolio Listing'!$C$7:$AF$28,3,FALSE) -> Diversified | J19: =VLOOKUP($C19,'Portfolio Listing'!$C$7:$AF$28,4,FALSE) -> PE - VC / Growth | K19: Private | L19: ='Portfolio Listing'!H20 -> 44166 | M19: =VLOOKUP(C19,'Portfolio Listing'!$C$7:$AF$28,7,FALSE) -> 15000000 | N19: =VLOOKUP(C19,'Portfolio Listing'!$C$7:$AF$28,8,FALSE) -> 15728508 | O19: =IF(N19-M19>0,0,N19-M19) -> 0 | Q19: =VLOOKUP(C19,'Portfolio Listing'!$C$7:$AF$28,11,FALSE) -> 2197607.1 | R19: =VLOOKUP(C19,'Portfolio Listing'!$C$7:$AF$28,12,FALSE) -> 0 | S19: =VLOOKUP(C19,'Portfolio Listing'!$C$7:$AF$28,14,FALSE) -> 11059809 | T19: =SUM(U19:AX19) -> 6771491.7 | U19: =U55+U79 -> 0 | V19: =V55+V79 -> 0 | W19: =W55+W79 -> 0 | X19: =X55+X79 -> 0 | Y19: =Y55+Y79 -> 0 | Z19: =Z55+Z79 -> 0 | AA19: =AA55+AA79 -> 0 | AB19: =AB55+AB79 -> 0 | ... AX19: =AX55+AX79 -> 0 | AZ19: =+INDEX('Portfolio Listing'!$AO$7:$AO$28,MATCH('Portfolio Summary'!$C19,'Portfolio Listing'!$C$7:$C$28,0)) -> Skycus USD Fund II ("Lionet Fund")
B20: =B19+1 -> 15 | C20: BOYU Real Estate Fund I | D20: =IRR(U20:AX20) -> 0.22333994 | E20: =T80/-T56 -> 2.3 | F20: =+INDEX('Portfolio Listing'!$U$7:$U$28,MATCH(C20,'Portfolio Listing'!$C$7:$C$28,0)) -> -0.095536217 | G20: ='Portfolio Listing'!T21 -> 0.84370343 | H20: =VLOOKUP($C20,'Portfolio Listing'!$C$7:$AF$28,2,FALSE) -> China | I20: =VLOOKUP($C20,'Portfolio Listing'!$C$7:$AF$28,3,FALSE) -> Logistic/ Data Center | J20: =VLOOKUP($C20,'Portfolio Listing'!$C$7:$AF$28,4,FALSE) -> PE - Real Estate | K20: Property | L20: ='Portfolio Listing'!H21 -> 44197 | M20: =VLOOKUP(C20,'Portfolio Listing'!$C$7:$AF$28,7,FALSE) -> 30000000 | N20: =VLOOKUP(C20,'Portfolio Listing'!$C$7:$AF$28,8,FALSE) -> 19364197 | O20: =IF(N20-M20>0,0,N20-M20) -> -10635803 | Q20: =VLOOKUP(C20,'Portfolio Listing'!$C$7:$AF$28,11,FALSE) -> 995489.23 | R20: =VLOOKUP(C20,'Portfolio Listing'!$C$7:$AF$28,12,FALSE) -> 0 | S20: =VLOOKUP(C20,'Portfolio Listing'!$C$7:$AF$28,14,FALSE) -> 15342150 | T20: =SUM(U20:AX20) -> 39000000 | U20: =U56+U80 -> 0 | V20: =V56+V80 -> 0 | W20: =W56+W80 -> 0 | X20: =X56+X80 -> 0 | Y20: =Y56+Y80 -> 0 | Z20: =Z56+Z80 -> 0 | AA20: =AA56+AA80 -> 0 | AB20: =AB56+AB80 -> 0 | ... AX20: =AX56+AX80 -> 0 | AZ20: =+INDEX('Portfolio Listing'!$AO$7:$AO$28,MATCH('Portfolio Summary'!$C20,'Portfolio Listing'!$C$7:$C$28,0)) -> Boyu Real Estate Fund I, LP
... B22: =B21+1 -> 17 | C22: Cottonwood | D22: =IRR(U22:AX22) -> 0.28061346 | E22: =T82/-T58 -> 2.51 | F22: =+INDEX('Portfolio Listing'!$U$7:$U$28,MATCH(C22,'Portfolio Listing'!$C$7:$C$28,0)) -> 0.44407232 | G22: ='Portfolio Listing'!T23 -> 1.1995842 | H22: =VLOOKUP($C22,'Portfolio Listing'!$C$7:$AF$28,2,FALSE) -> US | I22: =VLOOKUP($C22,'Portfolio Listing'!$C$7:$AF$28,3,FALSE) -> Real Estate | J22: =VLOOKUP($C22,'Portfolio Listing'!$C$7:$AF$28,4,FALSE) -> PE - Special Situations | K22: Private | L22: ='Portfolio Listing'!H23 -> 45393 | M22: =VLOOKUP(C22,'Portfolio Listing'!$C$7:$AF$28,7,FALSE) -> 12500000 | N22: =VLOOKUP(C22,'Portfolio Listing'!$C$7:$AF$28,8,FALSE) -> 3150647.5 | O22: =IF(N22-M22>0,0,N22-M22) -> -9349352.5 | Q22: =VLOOKUP(C22,'Portfolio Listing'!$C$7:$AF$28,11,FALSE) -> 0 | R22: =VLOOKUP(C22,'Portfolio Listing'!$C$7:$AF$28,12,FALSE) -> 0 | S22: =VLOOKUP(C22,'Portfolio Listing'!$C$7:$AF$28,14,FALSE) -> 3779467 | T22: =SUM(U22:AX22) -> 18875000 | U22: =U58+U82 -> 0 | V22: =V58+V82 -> 0 | W22: =W58+W82 -> 0 | X22: =X58+X82 -> 0 | Y22: =Y58+Y82 -> 0 | Z22: =Z58+Z82 -> 0 | AA22: =AA58+AA82 -> 0 | AB22: =AB58+AB82 -> 0 | ... AX22: =AX58+AX82 -> 0 | AZ22: =+INDEX('Portfolio Listing'!$AO$7:$AO$28,MATCH('Portfolio Summary'!$C22,'Portfolio Listing'!$C$7:$C$28,0)) -> Cottonwood-WTT Real Estate Special Situations Fund, LP
B23: =B22+1 -> 18 | C23: Genedant Ventures I | D23: =IRR(U23:AX23) -> 0.18861382 | E23: =T83/-T59 -> 3.5 | F23: =+INDEX('Portfolio Listing'!$U$7:$U$28,MATCH(C23,'Portfolio Listing'!$C$7:$C$28,0)) -> -0.67657796 | G23: ='Portfolio Listing'!T24 -> 0.73992472 | H23: =VLOOKUP($C23,'Portfolio Listing'!$C$7:$AF$28,2,FALSE) -> Global | I23: =VLOOKUP($C23,'Portfolio Listing'!$C$7:$AF$28,3,FALSE) -> Diversified | J23: =VLOOKUP($C23,'Portfolio Listing'!$C$7:$AF$28,4,FALSE) -> PE - VC / Growth | K23: VC | L23: 45518 | M23: =VLOOKUP(C23,'Portfolio Listing'!$C$7:$AF$28,7,FALSE) -> 37600000 | N23: =VLOOKUP(C23,'Portfolio Listing'!$C$7:$AF$28,8,FALSE) -> 2954733 | O23: =IF(N23-M23>0,0,N23-M23) -> -34645267 | Q23: =VLOOKUP(C23,'Portfolio Listing'!$C$7:$AF$28,11,FALSE) -> 0 | R23: =VLOOKUP(C23,'Portfolio Listing'!$C$7:$AF$28,12,FALSE) -> 0 | S23: =VLOOKUP(C23,'Portfolio Listing'!$C$7:$AF$28,14,FALSE) -> 2186280 | T23: =SUM(U23:AX23) -> 7386832.5 | U23: =U59+U83 -> 0 | V23: =V59+V83 -> 0 | W23: =W59+W83 -> 0 | X23: =X59+X83 -> 0 | Y23: =Y59+Y83 -> 0 | Z23: =Z59+Z83 -> 0 | AA23: =AA59+AA83 -> 0 | AB23: =AB59+AB83 -> 0 | ... AX23: =AX59+AX83 -> 0 | AZ23: =+INDEX('Portfolio Listing'!$AO$7:$AO$28,MATCH('Portfolio Summary'!$C23,'Portfolio Listing'!$C$7:$C$28,0)) -> Genedant Ventures I
B24: =B23+1 -> 19 | C24: GTCR XIV Access Offshore LP | D24: =IRR(U24:AX24) -> 0.22347825 | E24: =T84/-T60 -> 2.5 | F24: =+INDEX('Portfolio Listing'!$U$7:$U$28,MATCH(C24,'Portfolio Listing'!$C$7:$C$28,0)) -> 1.5680467 | G24: ='Portfolio Listing'!T25 -> 1.1920915 | H24: =VLOOKUP($C24,'Portfolio Listing'!$C$7:$AF$28,2,FALSE) -> US | I24: =VLOOKUP($C24,'Portfolio Listing'!$C$7:$AF$28,3,FALSE) -> Diversified | J24: =VLOOKUP($C24,'Portfolio Listing'!$C$7:$AF$28,4,FALSE) -> PE - Buyout | K24: VC | L24: 45261 | M24: =VLOOKUP(C24,'Portfolio Listing'!$C$7:$AF$28,7,FALSE) -> 16940000 | N24: =VLOOKUP(C24,'Portfolio Listing'!$C$7:$AF$28,8,FALSE) -> 1756064.1 | O24: =IF(N24-M24>0,0,N24-M24) -> -15183936 | Q24: =VLOOKUP(C24,'Portfolio Listing'!$C$7:$AF$28,11,FALSE) -> 0 | R24: =VLOOKUP(C24,'Portfolio Listing'!$C$7:$AF$28,12,FALSE) -> 0 | S24: =VLOOKUP(C24,'Portfolio Listing'!$C$7:$AF$28,14,FALSE) -> 2093389 | T24: =SUM(U24:AX24) -> 25410000 | U24: =U60+U84 -> 0 | V24: =V60+V84 -> 0 | W24: =W60+W84 -> 0 | X24: =X60+X84 -> 0 | Y24: =Y60+Y84 -> 0 | Z24: =Z60+Z84 -> 0 | AA24: =AA60+AA84 -> 0 | AB24: =AB60+AB84 -> 0 | ... AX24: =AX60+AX84 -> 0 | AZ24: =+INDEX('Portfolio Listing'!$AO$7:$AO$28,MATCH('Portfolio Summary'!$C24,'Portfolio Listing'!$C$7:$C$28,0)) -> GTCR XIV Access Offshore LP
D26: =IRR(U26:AR26) -> 0.19990547 | E26: =(Q26+R26+S26)/(M26+O26) -> 1.4469843 | M26: =SUM(M6:M25) -> 479290000 | N26: =SUM(N6:N25) -> 3.2951437e+08 | O26: =SUM(O6:O25) -> -1.6022981e+08 | Q26: =SUM(Q6:Q25) -> 2.2500713e+08 | R26: =SUM(R6:R25) -> 0 | S26: =SUM(S6:S25) -> 2.3666798e+08 | T26: =SUM(T6:T25) -> 4.3864604e+08 | U26: =SUM(U6:U25) -> -2738663.8 | V26: =SUM(V6:V25) -> -14361451 | W26: =SUM(W6:W25) -> -3014034.2 | X26: =SUM(X6:X25) -> -4327936.3 | ... AX26: =SUM(AX6:AX25) -> 0
U27: =+SUM($U$26:U26) -> -2738663.8 | V27: =+SUM($U$26:V26) -> -17100115 | W27: =+SUM($U$26:W26) -> -20114149 | X27: =+SUM($U$26:X26) -> -24442085 | Y27: =+SUM($U$26:Y26) -> -8788338 | Z27: =+SUM($U$26:Z26) -> -3362120.2 | AA27: =+SUM($U$26:AA26) -> 16730983 | AB27: =+SUM($U$26:AB26) -> 4857364 | ... AR27: =+SUM($U$26:AR26) -> 4.3864604e+08
B29: NOTES:
C30: 1. IRR is calculated based on forecast / expected future cashflow of the project / fund throughout the lifecycle
C31: 2. MoIC is calculated based on existing capital funding, distribution / sales proceeds and MTM Value
C32: 3. MTM Value is based on the the latest fund / project NAV report which may or may not reflect the potential capital upside of each fund / project
C33: 4. Some PE Projects will be managed by managed by Genedant after granting of RFM licence
C34: 5. Exited funds / projects are shaded in grey
C35: 6. O/S commitment to be funded in 5 to 10 years. Actual contribution may be less based on previous experience due to accelerated fund distribution and fund leverage
C36: *. Taikang Insurance is excluded from calculation of total as it has been syndicated out. The above shown is carried interest accrued.
B38: Kingsway Investment Ltd | M38: Capital Investment | Q38: Realized Value | S38: Unrealized Value | U38: 2011 | V38: =U38+1 -> 2012 | W38: =V38+1 -> 2013 | X38: =W38+1 -> 2014 | Y38: =X38+1 -> 2015 | Z38: =Y38+1 -> 2016 | AA38: =Z38+1 -> 2017 | AB38: =AA38+1 -> 2018 | AC38: =AB38+1 -> 2019 | ... AX38: =AW38+1 -> 2040
B39: No. | C39: PE Funds | K39: Nature | L39: Investment Date | M39: Committed | N39: Funded | O39: Unfunded (O/S) | Q39: Distribution | R39: Syndicated to Genedant | S39: MTM Value | T39: Total | U39: 0 | V39: =U39+1 -> 1 | W39: =V39+1 -> 2 | X39: =W39+1 -> 3 | Y39: =X39+1 -> 4 | Z39: =Y39+1 -> 5 | AA39: =Z39+1 -> 6 | AB39: =AA39+1 -> 7 | AC39: =AB39+1 -> 8 | ... AX39: =AW39+1 -> 29
B40: Cash Outflow
B41: 1 | C41: BOYU Capital Fund I | M41: =M6 -> 30000000 | T41: =SUM(U41:AX41) -> -29742026 | U41: ='BOYU Capital Fund I CF'!L10 -> -3026238.1 | V41: ='BOYU Capital Fund I CF'!L12+'BOYU Capital Fund I CF'!L14+'BOYU Capital Fund I CF'!L15+'BOYU Capital Fund I CF'!L16+'BOYU Capital Fund I CF'!L18 -> -13434435 | W41: ='BOYU Capital Fund I CF'!L20+'BOYU Capital Fund I CF'!L21+'BOYU Capital Fund I CF'!L23 -> -2311707 | X41: ='BOYU Capital Fund I CF'!L26+'BOYU Capital Fund I CF'!L27+'BOYU Capital Fund I CF'!L29+'BOYU Capital Fund I CF'!L30+'BOYU Capital Fund I CF'!L31+'BOYU Capital Fund I CF'!L34 -> -6199025.8 | Y41: ='BOYU Capital Fund I CF'!L36+'BOYU Capital Fund I CF'!L37+'BOYU Capital Fund I CF'!L40+'BOYU Capital Fund I CF'!L43+'BOYU Capital Fund I CF'!L46 -> -3309202 | Z41: ='BOYU Capital Fund I CF'!L49+'BOYU Capital Fund I CF'!L51+'BOYU Capital Fund I CF'!L52 -> -488498.82 | AA41: ='BOYU Capital Fund I CF'!L56+'BOYU Capital Fund I CF'!L60+'BOYU Capital Fund I CF'!L65 -> -273132.09 | AB41: ='BOYU Capital Fund I CF'!L66+'BOYU Capital Fund I CF'!L70 -> -182878.86 | AC41: ='BOYU Capital Fund I CF'!L72+'BOYU Capital Fund I CF'!L74+'BOYU Capital Fund I CF'!L77 -> -157424.58 | AD41: ='BOYU Capital Fund I CF'!L82+'BOYU Capital Fund I CF'!L85 -> -120277.23 | AE41: ='BOYU Capital Fund I CF'!L87+'BOYU Capital Fund I CF'!L90 -> -72816.23 | AF41: ='BOYU Capital Fund I CF'!L92+'BOYU Capital Fund I CF'!L94 -> -57293.78 | AG41: ='BOYU Capital Fund I CF'!L95+'BOYU Capital Fund I CF'!L96 -> -109097.3 | AH41: 0 | AI41: 0 | AJ41: 0 | AK41: 0 | AL41: 0 | AM41: 0 | AN41: 0 | AY41: Updated based on capital call estimate in 2025 from Boyu, expect no more further capital call.
B42: =B41+1 -> 2 | C42: Ascendent Fund | M42: =M7 -> 10000000 | T42: =SUM(U42:AX42) -> -9155663.4 | U42: 0 | V42: ='Ascendant CP I CF'!L11+'Ascendant CP I CF'!L12+'Ascendant CP I CF'!L13+'Ascendant CP I CF'!L15 -> -2938196.1 | W42: ='Ascendant CP I CF'!L17+'Ascendant CP I CF'!L18+'Ascendant CP I CF'!L19+'Ascendant CP I CF'!L20+'Ascendant CP I CF'!L21 -> -2121566.2 | X42: ='Ascendant CP I CF'!L22+'Ascendant CP I CF'!L24+'Ascendant CP I CF'!L25+'Ascendant CP I CF'!L26+'Ascendant CP I CF'!L31 -> -2214175.8 | Y42: ='Ascendant CP I CF'!L34+'Ascendant CP I CF'!L37 -> -1275365.5 | Z42: ='Ascendant CP I CF'!L38+'Ascendant CP I CF'!L40 -> -225358.24 | AA42: ='Ascendant CP I CF'!L42 -> -126777 | AB42: ='Ascendant CP I CF'!L45+'Ascendant CP I CF'!L46+'Ascendant CP I CF'!L47+'Ascendant CP I CF'!L49 -> -109918.94 | AC42: ='Ascendant CP I CF'!L51+'Ascendant CP I CF'!L52 -> -53912.04 | AD42: ='Ascendant CP I CF'!L53+'Ascendant CP I CF'!L54 -> -58314.38 | AE42: ='Ascendant CP I CF'!L56+'Ascendant CP I CF'!L58 -> -26929.11 | AF42: ='Ascendant CP I CF'!L61 -> -4396.94 | AG42: ='Ascendant CP I CF'!L63 -> -753.07 | AH42: 0 | AI42: 0 | AJ42: 0 | AK42: 0 | AL42: 0 | AM42: 0 | AN42: 0 | AY42: Commitment amount has been fully called
B43: =B42+1 -> 3 | C43: BOYU Capital Offshore Fund | M43: =M8 -> 10000000 | T43: =SUM(U43:AX43) -> -10000000 | U43: 0 | V43: 0 | W43: 0 | X43: 0 | Y43: 0 | Z43: -10000000 | AA43: 0 | AB43: 0 | AC43: 0 | AD43: 0 | AE43: 0 | AF43: 0 | AG43: 0 | AH43: 0 | AI43: 0 | AJ43: 0 | AK43: 0 | AL43: 0 | AM43: 0 | AN43: 0 | AY43: Commitment amount has been fully called
B44: =B43+1 -> 4 | C44: Ark Pacific Special Oppor Fund I | T44: =SUM(U44:AX44) -> -3413271.4 | U44: 0 | V44: 0 | W44: 0 | X44: 0 | Y44: -1973271.4 | Z44: 0 | AA44: -1440000 | AB44: 0 | AC44: 0 | AD44: 0 | AE44: 0 | AF44: 0 | AG44: 0 | AH44: 0 | AI44: 0 | AJ44: 0 | AK44: 0 | AL44: 0 | AM44: 0 | AN44: 0 | AY44: Commitment amount has been fully called
B45: =B44+1 -> 5 | C45: E15 Fund I | M45: =M9 -> 6000000 | T45: =SUM(U45:AX45) -> -6000000 | U45: 0 | V45: 0 | W45: 0 | X45: 0 | Y45: 0 | Z45: 0 | AA45: ='E15 Fund I (CF) '!J10+'E15 Fund I (CF) '!J11 -> -6000000 | AB45: 0 | AC45: 0 | AD45: 0 | AE45: 0 | AF45: 0 | AG45: 0 | AH45: 0 | AI45: 0 | AJ45: 0 | AK45: 0 | AL45: 0 | AM45: 0 | AN45: 0 | AY45: Commitment amount has been fully called
...

Sheet FUNDS >>

Sheet Ascendent CP I
A1: Fund Overview | D1: Fund Performance Indicator | E1: 45657 | H1: Fee Term
A2: Fund Full Name | B2: Ascendent Capital Partners I, L.P. | D2: Fair Value of Porfolio Companies (US$/mil) | E2: =W40 -> 6.4 | H2: Management fees - investment period | I2: 2% of commitment
A3: Initial Closing Date | B3: 40651 | D3: Total Net Asset Value (US$/mil) | E3: 9.490431 | H3: Management fees - after investment period | I3: 2% of invested capital
A4: Final Closing Date | B4: 41016 | D4: Fund Gross Multiple (x) | E4: 2.9 | H4: Preferred Return | I4: 0.08
A5: Vintage Year | B5: 2012 | D5: Fund Net Multiple (x) | E5: 2.1 | H5: Carried Interest | I5: 0.2
A6: General Partner ("GP") | B6: Ascendent Capital Partners I GP, L.P. | D6: Fund Gross IRR (%) | E6: 0.29 | H6: LP Reporting Timeline
A7: Investment Manager | B7: Ascendent Capital Partners Limited | D7: Fund Net IRR (%) | E7: 0.201 | H7: Quarterly report (after period end) | I7: 60 days
A8: Fund Domicile | B8: Cayman Islands | D8: Fund Distribution to Paid-in Capital (DPI %) | E8: =738.4/309.8 -> 2.3834732 | H8: Annual report (after period end) | I8: 120 days
A9: Fund Term | B9: 8 years from Final Closing Date | D9: CCG Performance Indicator
A10: Extensions | B10: 1 + 1 year | D10: Commitment (US$/mil) | E10: 10
A11: Investment Period | B11: 42277 | D11: Ownership % | E11: =10/365.4 -> 0.027367269
A12: Fund Currency | B12: USD | D12: Cumulative Contribution (US$/mil) | E12: =-'Ascendant CP I CF'!N2/10^6 -> 8.5702764
A13: Fund Size / Total Commitment | B13: US$365.4mil | D13: Remaining Unfunded Commitment (US$/mil) | E13: =E10-E12 -> 1.4297236
A14: Minimum Commitment | B14: US$10mil | D14: Cumulative Distribution (US$/mil) | E14: ='Ascendant CP I CF'!N3/10^6 -> 20.207464
A15: GP commitment | B15: US$21.5mil | D15: Capital Account Balance (US$/mil) | E15: ='Ascendant CP I CF'!N4/10^6 -> 0.249627
A16: Financial Year End | B16: 44196 | D16: Call-up Percentage (%) | E16: =E12/E10 -> 0.85702764
A17: Accounting Principles | B17: US GAAP | D17: Distribution to Paid-in Capital (DPI %) | E17: =E14/E12 -> 2.3578545
A18: Portfolio | D18: Multiple (x) | E18: =(E14+E15)/E12 -> 2.3869815
A19: Number of Portfolio Company | B19: 7 | D19: IRR (%) | E19: ='Ascendant CP I CF'!N5 -> 0.22429716
K30: Q4 2023 | T30: Q4 2024 | AC30: Q1 2025
A31: Portfolio | B31: Company Description | C31: Sector | D31: Status (Unrealized / Partial Realized / Realized / Write-off) | E31: First Investment Date | F31: IPO Date | G31: Ticker | H31: Exit Date | I31: Exit Method | J31: Holding Period (years) | K31: Investment Cost (USD/mil) | L31: % of Ownership | M31: Realized Value (USD/mil) | N31: Unrealized Value (USD/mil) | O31: Total Value (USD/mil) | P31: MOIC | Q31: IRR * | R31: Total Value - $ change YoY | S31: Total Value - % change YoY | T31: Investment Cost (USD/mil) | U31: % of Ownership | V31: Realized Value (USD/mil) | W31: Unrealized Value (USD/mil) | X31: Total Value (USD/mil) | Y31: MOIC | Z31: IRR * | AA31: Total Value - $ change YoY | AB31: Total Value - % change YoY | AC31: Investment Cost (USD/mil) | AD31: % of Ownership | AE31: Realized Value (USD/mil) | AF31: Unrealized Value (USD/mil) | AG31: Total Value (USD/mil) | AH31: MOIC | AI31: IRR * | AJ31: Total Value - $ change YoY | AK31: Total Value - % change YoY | AL31: Total Value - $ change QoQ | AM31: Total Value - % change QoQ
A32: WH Group Limited | B32: Previously under Shuanghui International; largest meat processor in China and pork producer in the world. | C32: Consumer | D32: Realized | E32: 40909 | J32: - | K32: 40.2 | L32: - | M32: 69.6 | N32: 0 | O32: =M32+N32 -> 69.6 | P32: =O32/K32 -> 1.7313433 | Q32: 0.232 | R32: 0 | S32: - | T32: 40.2 | U32: - | V32: 69.6 | W32: 0 | X32: =V32+W32 -> 69.6 | Y32: =X32/T32 -> 1.7313433 | Z32: 0 | AA32: =X32-O32 -> 0 | AB32: =IFERROR(X32/O32-1,0) -> 0
A33: Nano Resources Limited | B33: SPV to acquire Tong Dai, a railway supplier of parts for high speed trains in China. | C33: Industrials | D33: Realized | E33: 41244 | J33: - | K33: 32 | L33: - | M33: 163.1 | N33: 0 | O33: =N33+M33 -> 163.1 | P33: =O33/K33 -> 5.096875 | Q33: 0.649 | R33: 0 | S33: - | T33: 32 | U33: - | V33: 163.1 | W33: 0 | X33: =W33+V33 -> 163.1 | Y33: =X33/T33 -> 5.096875 | Z33: 0 | AA33: =X33-O33 -> 0 | AB33: =IFERROR(X33/O33-1,0) -> 0
A34: CFP Incorporated | B34: One of the largest metal packaging suppliers in China for consumer goods such as beverages and food products. | C34: Consumer | D34: Realized | E34: 41395 | J34: - | K34: 70 | L34: - | M34: 140.3 | N34: 0 | O34: =N34+M34 -> 140.3 | P34: =O34/K34 -> 2.0042857 | Q34: 0.223 | R34: 0 | S34: - | T34: 70 | U34: - | V34: 140.3 | W34: 0 | X34: =W34+V34 -> 140.3 | Y34: =X34/T34 -> 2.0042857 | Z34: 0 | AA34: =X34-O34 -> 0 | AB34: =IFERROR(X34/O34-1,0) -> 0
A35: Internet Plus Holdings Ltd | B35: One of largest online to offline platforms in China for local consumer products and retail services, monetizing on advertising solutions. | C35: Consumer | D35: Realized | E35: 42005 | J35: =YEAR(H35)-YEAR(E35) -> -115 | K35: 20 | L35: - | M35: 49.9 | N35: 0 | O35: =N35+M35 -> 49.9 | P35: =O35/K35 -> 2.495 | Q35: 0.284 | R35: 0 | S35: - | T35: 20 | U35: - | V35: 49.9 | W35: 0 | X35: =W35+V35 -> 49.9 | Y35: =X35/T35 -> 2.495 | Z35: 0 | AA35: =X35-O35 -> 0 | AB35: =IFERROR(X35/O35-1,0) -> 0
A36: Ningxia Harmony Dairy | B36: Regional dairy company in north China under the name of "Xiajin" | C36: Consumer | D36: Realized | E36: 41791 | J36: - | K36: 46 | L36: - | M36: 100.5 | N36: 0 | O36: =N36+M36 -> 100.5 | P36: =O36/K36 -> 2.1847826 | Q36: 0.131 | R36: 0 | S36: - | T36: 46 | U36: - | V36: 100.5 | W36: 0 | X36: =W36+V36 -> 100.5 | Y36: =X36/T36 -> 2.1847826 | Z36: 0 | AA36: =X36-O36 -> 0 | AB36: =IFERROR(X36/O36-1,0) -> 0
A37: Yongding Healthcare Management | B37: Ownership of YD Hospital, a Grade II general hospital and 2nd largest general hospital in Wujiang, Suzhou providing basic medical services to local residents. | C37: Healthcare | D37: Realized | E37: 41791 | J37: - | K37: 36.3 | L37: - | M37: 199 | N37: 0 | O37: =N37+M37 -> 199 | P37: =O37/K37 -> 5.4820937 | Q37: 0.307 | R37: 0 | S37: - | T37: 36.3 | U37: - | V37: 199 | W37: 0 | X37: =W37+V37 -> 199 | Y37: =X37/T37 -> 5.4820937 | Z37: 0 | AA37: =X37-O37 -> 0 | AB37: =IFERROR(X37/O37-1,0) -> 0
A38: Yan'an Pharmaceutical | B38: Generic pharmaceutical production to sell in county/rural drugstores, community healthcare centres and private clinics across 18 provinces | C38: Healthcare | D38: Partial Realized | E38: 42248 | F38: - | G38: - | H38: - | I38: - | J38: - | K38: 16.2 | L38: - | M38: 16.5 | N38: 8.2 | O38: =N38+M38 -> 24.7 | P38: =O38/K38 -> 1.5246914 | Q38: 0.056 | R38: 0 | S38: - | T38: 16.2 | U38: - | V38: 19.2 | W38: 6.4 | X38: =W38+V38 -> 25.6 | Y38: =X38/T38 -> 1.5802469 | Z38: 0 | AA38: =X38-O38 -> 0.9 | AB38: =IFERROR(X38/O38-1,0) -> 0.036437247
